Traceback (most recent call last):--------------------------------------------------------------------| 0.00% [0/4000 00:00<?]
  File "/home/tsl2b/.conda/envs/Bayesian_Docking_Score_Predictor/lib/python3.11/site-packages/pytensor/compile/function/types.py", line 970, in __call__
    self.vm()
  File "/home/tsl2b/.conda/envs/Bayesian_Docking_Score_Predictor/lib/python3.11/site-packages/pytensor/graph/op.py", line 549, in rval
    r = p(n, [x[0] for x in i], o)
        ^^^^^^^^^^^^^^^^^^^^^^^^^^
  File "/home/tsl2b/.conda/envs/Bayesian_Docking_Score_Predictor/lib/python3.11/site-packages/pytensor/tensor/random/op.py", line 340, in perform
    smpl_val = self.rng_fn(rng, *(args + [size]))
               ^^^^^^^^^^^^^^^^^^^^^^^^^^^^^^^^^^
  File "/home/tsl2b/.conda/envs/Bayesian_Docking_Score_Predictor/lib/python3.11/site-packages/pytensor/tensor/random/op.py", line 129, in rng_fn
    return getattr(rng, self.name)(*args, **kwargs)
           ^^^^^^^^^^^^^^^^^^^^^^^^^^^^^^^^^^^^^^^^
  File "numpy/random/_generator.pyx", line 1220, in numpy.random._generator.Generator.normal
  File "_common.pyx", line 600, in numpy.random._common.cont
  File "_common.pyx", line 517, in numpy.random._common.cont_broadcast_2
  File "__init__.cython-30.pxd", line 780, in numpy.PyArray_MultiIterNew3
ValueError: shape mismatch: objects cannot be broadcast to a single shape.  Mismatch is between arg 0 with shape (66289,) and arg 1 with shape (2054937,).

During handling of the above exception, another exception occurred:

Traceback (most recent call last):
  File "/sfs/qumulo/qhome/tsl2b/Documents/Bayesian_Docking-Score_Predictor/Predict_Response_Values.py", line 329, in <module>
    main(
  File "/sfs/qumulo/qhome/tsl2b/Documents/Bayesian_Docking-Score_Predictor/Predict_Response_Values.py", line 235, in main
    inference_data_for_posterior_predictive_probability_density_distribution_for_testing_data = pymc.sample_posterior_predictive(
                                                                                                ^^^^^^^^^^^^^^^^^^^^^^^^^^^^^^^^^
  File "/home/tsl2b/.conda/envs/Bayesian_Docking_Score_Predictor/lib/python3.11/site-packages/pymc/sampling/forward.py", line 644, in sample_posterior_predictive
    values = sampler_fn(**param)
             ^^^^^^^^^^^^^^^^^^^
  File "/home/tsl2b/.conda/envs/Bayesian_Docking_Score_Predictor/lib/python3.11/site-packages/pymc/util.py", line 393, in wrapped
    return core_function(**input_point)
           ^^^^^^^^^^^^^^^^^^^^^^^^^^^^
  File "/home/tsl2b/.conda/envs/Bayesian_Docking_Score_Predictor/lib/python3.11/site-packages/pytensor/compile/function/types.py", line 983, in __call__
    raise_with_op(
  File "/home/tsl2b/.conda/envs/Bayesian_Docking_Score_Predictor/lib/python3.11/site-packages/pytensor/link/utils.py", line 531, in raise_with_op
    raise exc_value.with_traceback(exc_trace)
  File "/home/tsl2b/.conda/envs/Bayesian_Docking_Score_Predictor/lib/python3.11/site-packages/pytensor/compile/function/types.py", line 970, in __call__
    self.vm()
  File "/home/tsl2b/.conda/envs/Bayesian_Docking_Score_Predictor/lib/python3.11/site-packages/pytensor/graph/op.py", line 549, in rval
    r = p(n, [x[0] for x in i], o)
        ^^^^^^^^^^^^^^^^^^^^^^^^^^
  File "/home/tsl2b/.conda/envs/Bayesian_Docking_Score_Predictor/lib/python3.11/site-packages/pytensor/tensor/random/op.py", line 340, in perform
    smpl_val = self.rng_fn(rng, *(args + [size]))
               ^^^^^^^^^^^^^^^^^^^^^^^^^^^^^^^^^^
  File "/home/tsl2b/.conda/envs/Bayesian_Docking_Score_Predictor/lib/python3.11/site-packages/pytensor/tensor/random/op.py", line 129, in rng_fn
    return getattr(rng, self.name)(*args, **kwargs)
           ^^^^^^^^^^^^^^^^^^^^^^^^^^^^^^^^^^^^^^^^
  File "numpy/random/_generator.pyx", line 1220, in numpy.random._generator.Generator.normal
  File "_common.pyx", line 600, in numpy.random._common.cont
  File "_common.pyx", line 517, in numpy.random._common.cont_broadcast_2
  File "__init__.cython-30.pxd", line 780, in numpy.PyArray_MultiIterNew3
ValueError: shape mismatch: objects cannot be broadcast to a single shape.  Mismatch is between arg 0 with shape (66289,) and arg 1 with shape (2054937,).
Apply node that caused the error: normal_rv{0, (0, 0), floatX, True}(RandomGeneratorSharedVariable(<Generator(PCG64) at 0x7F0AB112F140>), [66289], 11, Mul.0, P(sigma))
Toposort index: 10
Inputs types: [RandomGeneratorType, TensorType(int64, shape=(1,)), TensorType(int64, shape=()), TensorType(float64, shape=(None,)), TensorType(float64, shape=())]
Inputs shapes: ['No shapes', (1,), (), (2054937,), ()]
Inputs strides: ['No strides', (8,), (), (8,), ()]
Inputs values: [Generator(PCG64) at 0x7F0AB112F140, array([66289]), array(11), 'not shown', array(0.77465577)]
Outputs clients: [['output'], ['output']]

HINT: Re-running with most PyTensor optimizations disabled could provide a back-trace showing when this node was created. This can be done by setting the PyTensor flag 'optimizer=fast_compile'. If that does not work, PyTensor optimizations can be disabled with 'optimizer=None'.
HINT: Use the PyTensor flag `exception_verbosity=high` for a debug print-out and storage map footprint of this Apply node.
Sampling: [P(response value | mu, sigma)]█████████████████████████████████████████████████████████████| 100.00% [4000/4000 03:55<00:00]
Traceback (most recent call last):--------------------------------------------------------------------| 0.00% [0/4000 00:00<?]
  File "/home/tsl2b/.conda/envs/Bayesian_Docking_Score_Predictor/lib/python3.11/site-packages/pytensor/compile/function/types.py", line 970, in __call__
    self.vm()
  File "/home/tsl2b/.conda/envs/Bayesian_Docking_Score_Predictor/lib/python3.11/site-packages/pytensor/graph/op.py", line 549, in rval
    r = p(n, [x[0] for x in i], o)
        ^^^^^^^^^^^^^^^^^^^^^^^^^^
  File "/home/tsl2b/.conda/envs/Bayesian_Docking_Score_Predictor/lib/python3.11/site-packages/pytensor/tensor/random/op.py", line 340, in perform
    smpl_val = self.rng_fn(rng, *(args + [size]))
               ^^^^^^^^^^^^^^^^^^^^^^^^^^^^^^^^^^
  File "/home/tsl2b/.conda/envs/Bayesian_Docking_Score_Predictor/lib/python3.11/site-packages/pytensor/tensor/random/op.py", line 129, in rng_fn
    return getattr(rng, self.name)(*args, **kwargs)
           ^^^^^^^^^^^^^^^^^^^^^^^^^^^^^^^^^^^^^^^^
  File "numpy/random/_generator.pyx", line 1220, in numpy.random._generator.Generator.normal
  File "_common.pyx", line 600, in numpy.random._common.cont
  File "_common.pyx", line 517, in numpy.random._common.cont_broadcast_2
  File "__init__.cython-30.pxd", line 780, in numpy.PyArray_MultiIterNew3
ValueError: shape mismatch: objects cannot be broadcast to a single shape.  Mismatch is between arg 0 with shape (66289,) and arg 1 with shape (2054937,).

During handling of the above exception, another exception occurred:

Traceback (most recent call last):
  File "/sfs/qumulo/qhome/tsl2b/Documents/Bayesian_Docking-Score_Predictor/Predict_Response_Values.py", line 329, in <module>
    main(
  File "/sfs/qumulo/qhome/tsl2b/Documents/Bayesian_Docking-Score_Predictor/Predict_Response_Values.py", line 235, in main
    inference_data_for_posterior_predictive_probability_density_distribution_for_testing_data = pymc.sample_posterior_predictive(
                                                                                                ^^^^^^^^^^^^^^^^^^^^^^^^^^^^^^^^^
  File "/home/tsl2b/.conda/envs/Bayesian_Docking_Score_Predictor/lib/python3.11/site-packages/pymc/sampling/forward.py", line 644, in sample_posterior_predictive
    values = sampler_fn(**param)
             ^^^^^^^^^^^^^^^^^^^
  File "/home/tsl2b/.conda/envs/Bayesian_Docking_Score_Predictor/lib/python3.11/site-packages/pymc/util.py", line 393, in wrapped
    return core_function(**input_point)
           ^^^^^^^^^^^^^^^^^^^^^^^^^^^^
  File "/home/tsl2b/.conda/envs/Bayesian_Docking_Score_Predictor/lib/python3.11/site-packages/pytensor/compile/function/types.py", line 983, in __call__
    raise_with_op(
  File "/home/tsl2b/.conda/envs/Bayesian_Docking_Score_Predictor/lib/python3.11/site-packages/pytensor/link/utils.py", line 531, in raise_with_op
    raise exc_value.with_traceback(exc_trace)
  File "/home/tsl2b/.conda/envs/Bayesian_Docking_Score_Predictor/lib/python3.11/site-packages/pytensor/compile/function/types.py", line 970, in __call__
    self.vm()
  File "/home/tsl2b/.conda/envs/Bayesian_Docking_Score_Predictor/lib/python3.11/site-packages/pytensor/graph/op.py", line 549, in rval
    r = p(n, [x[0] for x in i], o)
        ^^^^^^^^^^^^^^^^^^^^^^^^^^
  File "/home/tsl2b/.conda/envs/Bayesian_Docking_Score_Predictor/lib/python3.11/site-packages/pytensor/tensor/random/op.py", line 340, in perform
    smpl_val = self.rng_fn(rng, *(args + [size]))
               ^^^^^^^^^^^^^^^^^^^^^^^^^^^^^^^^^^
  File "/home/tsl2b/.conda/envs/Bayesian_Docking_Score_Predictor/lib/python3.11/site-packages/pytensor/tensor/random/op.py", line 129, in rng_fn
    return getattr(rng, self.name)(*args, **kwargs)
           ^^^^^^^^^^^^^^^^^^^^^^^^^^^^^^^^^^^^^^^^
  File "numpy/random/_generator.pyx", line 1220, in numpy.random._generator.Generator.normal
  File "_common.pyx", line 600, in numpy.random._common.cont
  File "_common.pyx", line 517, in numpy.random._common.cont_broadcast_2
  File "__init__.cython-30.pxd", line 780, in numpy.PyArray_MultiIterNew3
ValueError: shape mismatch: objects cannot be broadcast to a single shape.  Mismatch is between arg 0 with shape (66289,) and arg 1 with shape (2054937,).
Apply node that caused the error: normal_rv{0, (0, 0), floatX, True}(RandomGeneratorSharedVariable(<Generator(PCG64) at 0x7F0AB112F140>), [66289], 11, Mul.0, P(sigma))
Toposort index: 10
Inputs types: [RandomGeneratorType, TensorType(int64, shape=(1,)), TensorType(int64, shape=()), TensorType(float64, shape=(None,)), TensorType(float64, shape=())]
Inputs shapes: ['No shapes', (1,), (), (2054937,), ()]
Inputs strides: ['No strides', (8,), (), (8,), ()]
Inputs values: [Generator(PCG64) at 0x7F0AB112F140, array([66289]), array(11), 'not shown', array(0.77465577)]
Outputs clients: [['output'], ['output']]

HINT: Re-running with most PyTensor optimizations disabled could provide a back-trace showing when this node was created. This can be done by setting the PyTensor flag 'optimizer=fast_compile'. If that does not work, PyTensor optimizations can be disabled with 'optimizer=None'.
HINT: Use the PyTensor flag `exception_verbosity=high` for a debug print-out and storage map footprint of this Apply node.
Sampling: [P(response value | mu, sigma)]█████████████████████████████████████████████████████████████| 100.00% [4000/4000 03:55<00:00]
Traceback (most recent call last):--------------------------------------------------------------------| 0.00% [0/4000 00:00<?]
  File "/home/tsl2b/.conda/envs/Bayesian_Docking_Score_Predictor/lib/python3.11/site-packages/pytensor/compile/function/types.py", line 970, in __call__
    self.vm()
  File "/home/tsl2b/.conda/envs/Bayesian_Docking_Score_Predictor/lib/python3.11/site-packages/pytensor/graph/op.py", line 549, in rval
    r = p(n, [x[0] for x in i], o)
        ^^^^^^^^^^^^^^^^^^^^^^^^^^
  File "/home/tsl2b/.conda/envs/Bayesian_Docking_Score_Predictor/lib/python3.11/site-packages/pytensor/tensor/random/op.py", line 340, in perform
    smpl_val = self.rng_fn(rng, *(args + [size]))
               ^^^^^^^^^^^^^^^^^^^^^^^^^^^^^^^^^^
  File "/home/tsl2b/.conda/envs/Bayesian_Docking_Score_Predictor/lib/python3.11/site-packages/pytensor/tensor/random/op.py", line 129, in rng_fn
    return getattr(rng, self.name)(*args, **kwargs)
           ^^^^^^^^^^^^^^^^^^^^^^^^^^^^^^^^^^^^^^^^
  File "numpy/random/_generator.pyx", line 1220, in numpy.random._generator.Generator.normal
  File "_common.pyx", line 600, in numpy.random._common.cont
  File "_common.pyx", line 517, in numpy.random._common.cont_broadcast_2
  File "__init__.cython-30.pxd", line 780, in numpy.PyArray_MultiIterNew3
ValueError: shape mismatch: objects cannot be broadcast to a single shape.  Mismatch is between arg 0 with shape (66289,) and arg 1 with shape (2054937,).

During handling of the above exception, another exception occurred:

Traceback (most recent call last):
  File "/sfs/qumulo/qhome/tsl2b/Documents/Bayesian_Docking-Score_Predictor/Predict_Response_Values.py", line 329, in <module>
    main(
  File "/sfs/qumulo/qhome/tsl2b/Documents/Bayesian_Docking-Score_Predictor/Predict_Response_Values.py", line 235, in main
    inference_data_for_posterior_predictive_probability_density_distribution_for_testing_data = pymc.sample_posterior_predictive(
                                                                                                ^^^^^^^^^^^^^^^^^^^^^^^^^^^^^^^^^
  File "/home/tsl2b/.conda/envs/Bayesian_Docking_Score_Predictor/lib/python3.11/site-packages/pymc/sampling/forward.py", line 644, in sample_posterior_predictive
    values = sampler_fn(**param)
             ^^^^^^^^^^^^^^^^^^^
  File "/home/tsl2b/.conda/envs/Bayesian_Docking_Score_Predictor/lib/python3.11/site-packages/pymc/util.py", line 393, in wrapped
    return core_function(**input_point)
           ^^^^^^^^^^^^^^^^^^^^^^^^^^^^
  File "/home/tsl2b/.conda/envs/Bayesian_Docking_Score_Predictor/lib/python3.11/site-packages/pytensor/compile/function/types.py", line 983, in __call__
    raise_with_op(
  File "/home/tsl2b/.conda/envs/Bayesian_Docking_Score_Predictor/lib/python3.11/site-packages/pytensor/link/utils.py", line 531, in raise_with_op
    raise exc_value.with_traceback(exc_trace)
  File "/home/tsl2b/.conda/envs/Bayesian_Docking_Score_Predictor/lib/python3.11/site-packages/pytensor/compile/function/types.py", line 970, in __call__
    self.vm()
  File "/home/tsl2b/.conda/envs/Bayesian_Docking_Score_Predictor/lib/python3.11/site-packages/pytensor/graph/op.py", line 549, in rval
    r = p(n, [x[0] for x in i], o)
        ^^^^^^^^^^^^^^^^^^^^^^^^^^
  File "/home/tsl2b/.conda/envs/Bayesian_Docking_Score_Predictor/lib/python3.11/site-packages/pytensor/tensor/random/op.py", line 340, in perform
    smpl_val = self.rng_fn(rng, *(args + [size]))
               ^^^^^^^^^^^^^^^^^^^^^^^^^^^^^^^^^^
  File "/home/tsl2b/.conda/envs/Bayesian_Docking_Score_Predictor/lib/python3.11/site-packages/pytensor/tensor/random/op.py", line 129, in rng_fn
    return getattr(rng, self.name)(*args, **kwargs)
           ^^^^^^^^^^^^^^^^^^^^^^^^^^^^^^^^^^^^^^^^
  File "numpy/random/_generator.pyx", line 1220, in numpy.random._generator.Generator.normal
  File "_common.pyx", line 600, in numpy.random._common.cont
  File "_common.pyx", line 517, in numpy.random._common.cont_broadcast_2
  File "__init__.cython-30.pxd", line 780, in numpy.PyArray_MultiIterNew3
ValueError: shape mismatch: objects cannot be broadcast to a single shape.  Mismatch is between arg 0 with shape (66289,) and arg 1 with shape (2054937,).
Apply node that caused the error: normal_rv{0, (0, 0), floatX, True}(RandomGeneratorSharedVariable(<Generator(PCG64) at 0x7F0AB112F140>), [66289], 11, Mul.0, P(sigma))
Toposort index: 10
Inputs types: [RandomGeneratorType, TensorType(int64, shape=(1,)), TensorType(int64, shape=()), TensorType(float64, shape=(None,)), TensorType(float64, shape=())]
Inputs shapes: ['No shapes', (1,), (), (2054937,), ()]
Inputs strides: ['No strides', (8,), (), (8,), ()]
Inputs values: [Generator(PCG64) at 0x7F0AB112F140, array([66289]), array(11), 'not shown', array(0.77465577)]
Outputs clients: [['output'], ['output']]

HINT: Re-running with most PyTensor optimizations disabled could provide a back-trace showing when this node was created. This can be done by setting the PyTensor flag 'optimizer=fast_compile'. If that does not work, PyTensor optimizations can be disabled with 'optimizer=None'.
HINT: Use the PyTensor flag `exception_verbosity=high` for a debug print-out and storage map footprint of this Apply node